Workbook

Sheet Raw data
A1: Branch Name | B1: Branch Code | C1: BranchLabels | D1: Business Brand | E1: Business Date | F1: Invoice Number | G1: Order Source | H1: Source Order Number | I1: Source Outlet Id | J1: Invoice Date | K1: Invoice Type | L1: Advance Order | M1: Gross Amount | N1: Discounts | O1: Direct Charge Amount | P1: Net Amount | Q1: Other Charge Amount | R1: Taxes | S1: Rounding | T1: Tip | U1: Total | V1: Paid Amount | W1: Balance Due | X1: Payment Modes | Y1: Materials Cost | Z1: Supplies Cost | AA1: Channel | AB1: Channel Label | AC1: Label | AD1: Session | AE1: Customer Id | AF1: Customer Name | AG1: Customer Phone | AH1: Customer Tax Id | AI1: Customer State | AJ1: Statement Number | AK1: Charges Amount (Initial) | AL1: Charges Amount (Removed) | AM1: Payment-Card | AN1: Payment-Cash | AO1: Payment-Dineout Pay | AP1: Payment-magicpin | AQ1: Payment-Magicpin Pay | AR1: Payment-Paytm | AS1: Payment-Swiggy | AT1: Payment-Zomato | AU1: Payment-Zomato District | AV1: CGST 2.5% Value | AW1: CGST 2.5% Amount | AX1: SGST 2.5% Value | AY1: SGST 2.5% Amount | AZ1: Account-Burgrill | BA1: Account-The Sausage Fest | BB1: Charge-Packing Charges | BC1: Charge-Restaurant Packaging Charges
A2: Store 1 | B2: 110027 | C2: Outlet | D2: Burgrill | E2: 45962 | F2: RJ390531 | G2: zomato | H2: 7430059910 | I2: 18528960 | J2: 45962.518 | K2: Sale | L2: No | M2: 257 | N2: 0 | O2: 0 | P2: 257 | Q2: 32 | R2: 0 | S2: 0 | T2: 0 | U2: 289 | V2: 289 | W2: 0 | X2: Zomato | Y2: 52.81 | Z2: 3.92 | AA2: Burgrill-Zomato | AB2: Burgrill | AC2: 9910 | AK2: 32 | AL2: 0 | AT2: 289 | AZ2: 257 | BC2: 32
A3: Store 1 | B3: 110027 | C3: Outlet | D3: Burgrill | E3: 45962 | F3: RJ390532 | G3: swiggy | H3: 220952000000000 | I3: 29811 | J3: 45962.544 | K3: Sale | L3: No | M3: 576 | N3: -93.74 | O3: 0 | P3: 482.26 | Q3: 32 | R3: 0 | S3: -0.26 | T3: 0 | U3: 514 | V3: 514 | W3: 0 | X3: Swiggy | Y3: 126.08 | Z3: 9.76 | AA3: Burgrill-Swiggy | AB3: Burgrill | AC3: 5597 | AK3: 32 | AL3: 0 | AS3: 514 | AZ3: 482.26 | BB3: 32
A4: Store 1 | B4: 110027 | C4: Outlet | D4: Burgrill | E4: 45962 | F4: RJ390530 | G4: POS | J4: 45962.565 | K4: Sale | L4: No | M4: 59 | N4: 0 | O4: 0 | P4: 59 | Q4: 0 | R4: 2.96 | S4: 0.04 | T4: 0 | U4: 62 | V4: 62 | W4: 0 | X4: Cash | Y4: 15.49 | Z4: 1.96 | AA4: Burgrill-Takeaway | AE4: 4VS4ZNEI | AF4: vipin | AG4: 9990930244 | AK4: 0 | AL4: 0 | AN4: 62 | AV4: 59 | AW4: 1.48 | AX4: 59 | AY4: 1.48 | AZ4: 59
A5: Store 1 | B5: 110027 | C5: Outlet | D5: Burgrill | E5: 45962 | F5: RJ390529 | G5: POS | J5: 45962.565 | K5: Sale | L5: No | M5: 159 | N5: 0 | O5: 0 | P5: 159 | Q5: 0 | R5: 7.96 | S5: 0.04 | T5: 0 | U5: 167 | V5: 167 | W5: 0 | X5: Card | Y5: 29.83 | Z5: 2.5 | AA5: Burgrill-Dine In | AB5: Dine In | AE5: R7ZUEYAL | AF5: naman | AG5: 9267927604 | AK5: 0 | AL5: 0 | AM5: 167 | AV5: 159 | AW5: 3.98 | AX5: 159 | AY5: 3.98 | AZ5: 159
A6: Store 1 | B6: 110027 | C6: Outlet | D6: Burgrill | E6: 45962 | F6: RJ390533 | G6: zomato | H6: 7436034135 | I6: 18528960 | J6: 45962.568 | K6: Sale | L6: No | M6: 418 | N6: -75 | O6: 0 | P6: 343 | Q6: 32 | R6: 0 | S6: 0 | T6: 0 | U6: 375 | V6: 375 | W6: 0 | X6: Zomato | Y6: 80.87 | Z6: 4.77 | AA6: Burgrill-Zomato | AB6: Burgrill | AC6: 4135 | AK6: 32 | AL6: 0 | AT6: 375 | AZ6: 343 | BC6: 32
A7: Store 1 | B7: 110027 | C7: Outlet | D7: Burgrill | E7: 45962 | F7: RJ390537 | G7: zomato | H7: 7436304288 | I7: 18528960 | J7: 45962.595 | K7: Sale | L7: No | M7: 359 | N7: -75 | O7: 0 | P7: 284 | Q7: 32 | R7: 0 | S7: 0 | T7: 0 | U7: 316 | V7: 316 | W7: 0 | X7: Zomato | Y7: 77.14 | Z7: 9.82 | AA7: Burgrill-Zomato | AB7: Burgrill | AC7: 4288 | AK7: 32 | AL7: 0 | AT7: 316 | AZ7: 284 | BC7: 32
A8: Store 1 | B8: 110027 | C8: Outlet | D8: Burgrill | E8: 45962 | F8: RJ390538 | G8: swiggy | H8: 220957000000000 | I8: 29811 | J8: 45962.6 | K8: Sale | L8: No | M8: 508 | N8: -200 | O8: 0 | P8: 308 | Q8: 32 | R8: 0 | S8: 0 | T8: 0 | U8: 340 | V8: 340 | W8: 0 | X8: Swiggy | Y8: 74.34 | Z8: 3.38 | AA8: Burgrill-Swiggy | AB8: Burgrill | AC8: 4258 | AK8: 32 | AL8: 0 | AS8: 340 | AZ8: 308 | BB8: 32
A9: Store 1 | B9: 110027 | C9: Outlet | D9: Burgrill | E9: 45962 | F9: RJ390539 | G9: zomato | H9: 7436617919 | I9: 18528960 | J9: 45962.612 | K9: Sale | L9: No | M9: 308 | N9: -100 | O9: 0 | P9: 208 | Q9: 32 | R9: 0 | S9: 0 | T9: 0 | U9: 240 | V9: 240 | W9: 0 | X9: Zomato | Y9: 56.44 | Z9: 10.56 | AA9: Burgrill-Zomato | AB9: Burgrill | AC9: 7919 | AK9: 32 | AL9: 0 | AT9: 240 | AZ9: 208 | BC9: 32
A10: Store 1 | B10: 110027 | C10: Outlet | D10: Burgrill | E10: 45962 | F10: RJ390540 | G10: swiggy | H10: 220958000000000 | I10: 29811 | J10: 45962.617 | K10: Sale | L10: No | M10: 508 | N10: -93.74 | O10: 0 | P10: 414.26 | Q10: 32 | R10: 0 | S10: -0.26 | T10: 0 | U10: 446 | V10: 446 | W10: 0 | X10: Swiggy | Y10: 94.86 | Z10: 13.74 | AA10: Burgrill-Swiggy | AB10: Burgrill | AC10: 7113 | AK10: 32 | AL10: 0 | AS10: 446 | AZ10: 414.26 | BB10: 32
A11: Store 1 | B11: 110027 | C11: Outlet | D11: Burgrill | E11: 45962 | F11: RJ390541 | G11: swiggy | H11: 220959000000000 | I11: 29811 | J11: 45962.624 | K11: Sale | L11: No | M11: 393.28 | N11: -93.75 | O11: 0 | P11: 299.53 | Q11: 32 | R11: 0 | S11: 0.47 | T11: 0 | U11: 332 | V11: 332 | W11: 0 | X11: Swiggy | Y11: 91.25 | Z11: 5.79 | AA11: Burgrill-Swiggy | AB11: Burgrill | AC11: 124 | AK11: 32 | AL11: 0 | AS11: 332 | AZ11: 299.53 | BB11: 32
A12: Store 1 | B12: 110027 | C12: Outlet | D12: Burgrill | E12: 45962 | F12: RJ390542 | G12: swiggy | H12: 220959000000000 | I12: 29811 | J12: 45962.626 | K12: Sale | L12: No | M12: 268 | N12: -93.75 | O12: 0 | P12: 174.25 | Q12: 32 | R12: 0 | S12: -0.25 | T12: 0 | U12: 206 | V12: 206 | W12: 0 | X12: Swiggy | Y12: 49.33 | Z12: 7.46 | AA12: Burgrill-Swiggy | AB12: Burgrill | AC12: 4459 | AK12: 32 | AL12: 0 | AS12: 206 | AZ12: 174.25 | BB12: 32
A13: Store 1 | B13: 110027 | C13: Outlet | D13: Burgrill | E13: 45962 | F13: RJ390543 | G13: zomato | H13: 7435937715 | I13: 18528960 | J13: 45962.64 | K13: Sale | L13: No | M13: 698 | N13: -349 | O13: 0 | P13: 349 | Q13: 32 | R13: 0 | S13: 0 | T13: 0 | U13: 381 | V13: 381 | W13: 0 | X13: Zomato | Y13: 129.66 | Z13: 9.54 | AA13: Burgrill-Zomato | AB13: Burgrill | AC13: 7715 | AK13: 32 | AL13: 0 | AT13: 381 | AZ13: 349 | BC13: 32
A14: Store 1 | B14: 110027 | C14: Outlet | D14: Burgrill | E14: 45962 | F14: RJ390544 | G14: zomato | H14: 7435794679 | I14: 18528960 | J14: 45962.65 | K14: Sale | L14: No | M14: 574.66 | N14: -199.5 | O14: 0 | P14: 375.16 | Q14: 32 | R14: 0 | S14: 0 | T14: 0 | U14: 407.16 | V14: 407.16 | W14: 0 | X14: Zomato | Y14: 99.34 | Z14: 4.06 | AA14: Burgrill-Zomato | AB14: Burgrill | AC14: 4679 | AK14: 32 | AL14: 0 | AT14: 407.16 | AZ14: 375.16 | BC14: 32
A15: Store 1 | B15: 110027 | C15: Outlet | D15: Burgrill | E15: 45962 | F15: RJ390545 | G15: swiggy | H15: 220962000000000 | I15: 29811 | J15: 45962.656 | K15: Sale | L15: No | M15: 258 | N15: -93.75 | O15: 0 | P15: 164.25 | Q15: 32 | R15: 0 | S15: -0.25 | T15: 0 | U15: 196 | V15: 196 | W15: 0 | X15: Swiggy | Y15: 48.54 | Z15: 7.02 | AA15: Burgrill-Swiggy | AB15: Burgrill | AC15: 3213 | AK15: 32 | AL15: 0 | AS15: 196 | AZ15: 164.25 | BB15: 32
A16: Store 1 | B16: 110027 | C16: Outlet | D16: Burgrill | E16: 45962 | F16: RJ390534 | G16: POS | J16: 45962.669 | K16: Sale | L16: No | M16: 288 | N16: 0 | O16: 0 | P16: 288 | Q16: 0 | R16: 14.4 | S16: -0.4 | T16: 0 | U16: 302 | V16: 302 | W16: 0 | X16: Card | Y16: 68.99 | Z16: 3.92 | AA16: Burgrill-Dine In | AB16: Dine In | AE16: RJFXN3YM | AF16: Burgrill | AG16: 8929758003 | AK16: 0 | AL16: 0 | AM16: 302 | AV16: 288 | AW16: 7.2 | AX16: 288 | AY16: 7.2 | AZ16: 288
A17: Store 1 | B17: 110027 | C17: Outlet | D17: Burgrill | E17: 45962 | F17: RJ390535 | G17: POS | J17: 45962.669 | K17: Sale | L17: No | M17: 356 | N17: 0 | O17: 0 | P17: 356 | Q17: 0 | R17: 17.8 | S17: 0.2 | T17: 0 | U17: 374 | V17: 374 | W17: 0 | X17: Card | Y17: 100.44 | Z17: 8.16 | AA17: Burgrill-Dine In | AB17: Dine In | AE17: BCTCUL8A | AF17: ms | AG17: 8171020359 | AK17: 0 | AL17: 0 | AM17: 374 | AV17: 356 | AW17: 8.9 | AX17: 356 | AY17: 8.9 | AZ17: 356
A18: Store 1 | B18: 110027 | C18: Outlet | D18: Burgrill | E18: 45962 | F18: RJ390536 | G18: POS | J18: 45962.669 | K18: Sale | L18: No | M18: 66.66 | N18: 0 | O18: 0 | P18: 66.66 | Q18: 0 | R18: 3.34 | S18: 0 | T18: 0 | U18: 70 | V18: 70 | W18: 0 | X18: Card | Y18: 25 | Z18: 0 | AA18: Burgrill-Dine In | AB18: Dine In | AE18: RJFXN3YM | AF18: Burgrill | AG18: 8929758003 | AK18: 0 | AL18: 0 | AM18: 70 | AV18: 66.66 | AW18: 1.67 | AX18: 66.66 | AY18: 1.67 | AZ18: 66.66
A19: Store 1 | B19: 110027 | C19: Outlet | D19: Burgrill | E19: 45962 | F19: RJ390546 | G19: swiggy | H19: 220963000000000 | I19: 29811 | J19: 45962.676 | K19: Sale | L19: No | M19: 545 | N19: -130 | O19: 0 | P19: 415 | Q19: 32 | R19: 0 | S19: 0 | T19: 0 | U19: 447 | V19: 447 | W19: 0 | X19: Swiggy | Y19: 99.73 | Z19: 9.8 | AA19: Burgrill-Swiggy | AB19: Burgrill | AC19: 5595 | AK19: 32 | AL19: 0 | AS19: 447 | AZ19: 415 | BB19: 32
A20: Store 1 | B20: 110027 | C20: Outlet | D20: Burgrill | E20: 45962 | F20: RJ390547 | G20: swiggy | H20: 220963000000000 | I20: 29811 | J20: 45962.677 | K20: Sale | L20: No | M20: 395 | N20: -74.99 | O20: 0 | P20: 320.01 | Q20: 32 | R20: 0 | S20: -0.01 | T20: 0 | U20: 352 | V20: 352 | W20: 0 | X20: Swiggy | Y20: 74.43 | Z20: 8.88 | AA20: Burgrill-Swiggy | AB20: Burgrill | AC20: 5423 | AK20: 32 | AL20: 0 | AS20: 352 | AZ20: 320.01 | BB20: 32
A21: Store 1 | B21: 110027 | C21: Outlet | D21: Burgrill | E21: 45962 | F21: RJ390549 | G21: POS | J21: 45962.697 | K21: Sale | L21: No | M21: 159 | N21: 0 | O21: 0 | P21: 159 | Q21: 0 | R21: 7.96 | S21: 0.04 | T21: 0 | U21: 167 | V21: 167 | W21: 0 | X21: Cash | Y21: 29.83 | Z21: 2.5 | AA21: Burgrill-Dine In | AB21: Dine In | AE21: E9WZ2UG5 | AF21: sidhi | AG21: 7817653551 | AK21: 0 | AL21: 0 | AN21: 167 | AV21: 159 | AW21: 3.98 | AX21: 159 | AY21: 3.98 | AZ21: 159
A22: Store 1 | B22: 110027 | C22: Outlet | D22: Burgrill | E22: 45962 | F22: RJ390550 | G22: swiggy | H22: 220966000000000 | I22: 29811 | J22: 45962.702 | K22: Sale | L22: No | M22: 646 | N22: -93.75 | O22: 0 | P22: 552.25 | Q22: 32 | R22: 0 | S22: -0.25 | T22: 0 | U22: 584 | V22: 584 | W22: 0 | X22: Swiggy | Y22: 150.41 | Z22: 14.78 | AA22: Burgrill-Swiggy | AB22: Burgrill | AC22: 379 | AK22: 32 | AL22: 0 | AS22: 584 | AZ22: 552.25 | BB22: 32
A23: Store 1 | B23: 110027 | C23: Outlet | D23: Burgrill | E23: 45962 | F23: RJ390551 | G23: POS | J23: 45962.706 | K23: Sale | L23: No | M23: 369 | N23: 0 | O23: 0 | P23: 369 | Q23: 0 | R23: 18.46 | S23: -0.46 | T23: 0 | U23: 387 | V23: 387 | W23: 0 | X23: Cash | Y23: 99.73 | Z23: 8.72 | AA23: Burgrill-Dine In | AB23: Dine In | AE23: GIDIRMS3 | AF23: hare krishna | AG23: 9999669771 | AK23: 0 | AL23: 0 | AN23: 387 | AV23: 369 | AW23: 9.23 | AX23: 369 | AY23: 9.23 | AZ23: 369
A24: Store 1 | B24: 110027 | C24: Outlet | D24: Burgrill | E24: 45962 | F24: RJ390554 | G24: zomato | H24: 7437673579 | I24: 18528960 | J24: 45962.71 | K24: Sale | L24: No | M24: 663.66 | N24: -248.9 | O24: 0 | P24: 414.76 | Q24: 32 | R24: 0 | S24: 0 | T24: 0 | U24: 446.76 | V24: 446.76 | W24: 0 | X24: Zomato | Y24: 135.43 | Z24: 10.95 | AA24: Burgrill-Zomato | AB24: Burgrill | AC24: 3579 | AK24: 32 | AL24: 0 | AT24: 446.76 | AZ24: 414.76 | BC24: 32
A25: Store 1 | B25: 110027 | C25: Outlet | D25: Burgrill | E25: 45962 | F25: RJ390558 | G25: swiggy | H25: 220968000000000 | I25: 29811 | J25: 45962.729 | K25: Sale | L25: No | M25: 318 | N25: -93.75 | O25: 0 | P25: 224.25 | Q25: 32 | R25: 0 | S25: -0.25 | T25: 0 | U25: 256 | V25: 256 | W25: 0 | X25: Swiggy | Y25: 70.61 | Z25: 4.77 | AA25: Burgrill-Swiggy | AB25: Burgrill | AC25: 9697 | AK25: 32 | AL25: 0 | AS25: 256 | AZ25: 224.25 | BB25: 32
A26: Store 1 | B26: 110027 | C26: Outlet | D26: Burgrill | E26: 45962 | F26: RJ390559 | G26: swiggy | H26: 220968000000000 | I26: 29811 | J26: 45962.731 | K26: Sale | L26: No | M26: 178 | N26: -20 | O26: 0 | P26: 158 | Q26: 32 | R26: 0 | S26: 0 | T26: 0 | U26: 190 | V26: 190 | W26: 0 | X26: Swiggy | Y26: 37.92 | Z26: 1.96 | AA26: Burgrill-Swiggy | AB26: Burgrill | AC26: 6720 | AK26: 32 | AL26: 0 | AS26: 190 | AZ26: 158 | BB26: 32
A27: Store 1 | B27: 110027 | C27: Outlet | D27: Burgrill | E27: 45962 | F27: RJ390560 | G27: zomato | H27: 7431959854 | I27: 18528960 | J27: 45962.74 | K27: Sale | L27: No | M27: 1036 | N27: 0 | O27: 0 | P27: 1036 | Q27: 32 | R27: 0 | S27: 0 | T27: 0 | U27: 1068 | V27: 1068 | W27: 0 | X27: Zomato | Y27: 233.97 | Z27: 19.36 | AA27: Burgrill-Zomato | AB27: Burgrill | AC27: 9854 | AK27: 32 | AL27: 0 | AT27: 1068 | AZ27: 1036 | BC27: 32
A28: Store 1 | B28: 110027 | C28: Outlet | D28: Burgrill | E28: 45962 | F28: RJ390564 | G28: POS | J28: 45962.772 | K28: Sale | L28: No | M28: 198 | N28: 0 | O28: 0 | P28: 198 | Q28: 0 | R28: 9.9 | S28: 0.1 | T28: 0 | U28: 208 | V28: 208 | W28: 0 | X28: Cash | Y28: 48.85 | Z28: 3.92 | AA28: Burgrill-Dine In | AB28: Dine In | AE28: RJFXN3YM | AF28: Burgrill | AG28: 8929758003 | AK28: 0 | AL28: 0 | AN28: 208 | AV28: 198 | AW28: 4.95 | AX28: 198 | AY28: 4.95 | AZ28: 198
A29: Store 1 | B29: 110027 | C29: Outlet | D29: Burgrill | E29: 45962 | F29: RJ390563 | G29: POS | J29: 45962.772 | K29: Sale | L29: No | M29: 217 | N29: -15 | O29: 0 | P29: 202 | Q29: 0 | R29: 10.1 | S29: -0.1 | T29: 0 | U29: 212 | V29: 212 | W29: 0 | X29: Cash,Card | Y29: 56.03 | Z29: 5.88 | AA29: Burgrill-Takeaway | AE29: I8Y3EPU8 | AF29: shivam | AG29: 9810206362 | AK29: 0 | AL29: 0 | AM29: 12 | AN29: 200 | AV29: 202 | AW29: 5.05 | AX29: 202 | AY29: 5.05 | AZ29: 202
A30: Store 1 | B30: 110027 | C30: Outlet | D30: Burgrill | E30: 45962 | F30: RJ390562 | G30: POS | J30: 45962.772 | K30: Sale | L30: No | M30: 356 | N30: 0 | O30: 0 | P30: 356 | Q30: 0 | R30: 17.8 | S30: 0.2 | T30: 0 | U30: 374 | V30: 374 | W30: 0 | X30: Card | Y30: 97.33 | Z30: 8.16 | AA30: Burgrill-Dine In | AB30: Dine In | AE30: RJFXN3YM | AF30: Burgrill | AG30: 8929758003 | AK30: 0 | AL30: 0 | AM30: 374 | AV30: 356 | AW30: 8.9 | AX30: 356 | AY30: 8.9 | AZ30: 356
A31: Store 1 | B31: 110027 | C31: Outlet | D31: Burgrill | E31: 45962 | F31: RJ390561 | G31: POS | J31: 45962.772 | K31: Sale | L31: No | M31: 348 | N31: 0 | O31: 0 | P31: 348 | Q31: 0 | R31: 17.4 | S31: -0.4 | T31: 0 | U31: 365 | V31: 365 | W31: 0 | X31: Card | Y31: 97.24 | Z31: 4.52 | AA31: Burgrill-Dine In | AB31: Dine In | AE31: RJFXN3YM | AF31: Burgrill | AG31: 8929758003 | AK31: 0 | AL31: 0 | AM31: 365 | AV31: 348 | AW31: 8.7 | AX31: 348 | AY31: 8.7 | AZ31: 348
A32: Store 1 | B32: 110027 | C32: Outlet | D32: Burgrill | E32: 45962 | F32: RJ390557 | G32: POS | J32: 45962.772 | K32: Sale | L32: No | M32: 597 | N32: 0 | O32: 0 | P32: 597 | Q32: 0 | R32: 29.86 | S32: 0.14 | T32: 0 | U32: 627 | V32: 627 | W32: 0 | X32: Card | Y32: 142.23 | Z32: 7.68 | AA32: Burgrill-Dine In | AB32: Dine In | AE32: MJHTLH2P | AF32: asveed | AG32: 8287834046 | AK32: 0 | AL32: 0 | AM32: 627 | AV32: 597 | AW32: 14.93 | AX32: 597 | AY32: 14.93 | AZ32: 597
A33: Store 1 | B33: 110027 | C33: Outlet | D33: Burgrill | E33: 45962 | F33: RJ390556 | G33: POS | J33: 45962.773 | K33: Sale | L33: No | M33: 594.1 | N33: 0 | O33: 0 | P33: 594.1 | Q33: 0 | R33: 29.7 | S33: 0.2 | T33: 0 | U33: 624 | V33: 624 | W33: 0 | X33: Cash,Card | Y33: 171.65 | Z33: 8.86 | AA33: Burgrill-Dine In | AB33: Dine In | AE33: RJFXN3YM | AF33: Burgrill | AG33: 8929758003 | AK33: 0 | AL33: 0 | AM33: 124 | AN33: 500 | AV33: 594.1 | AW33: 14.85 | AX33: 594.1 | AY33: 14.85 | AZ33: 594.1
A34: Store 1 | B34: 110027 | C34: Outlet | D34: Burgrill | E34: 45962 | F34: RJ390553 | G34: POS | J34: 45962.773 | K34: Sale | L34: No | M34: 369 | N34: 0 | O34: 0 | P34: 369 | Q34: 0 | R34: 18.46 | S34: -0.46 | T34: 0 | U34: 387 | V34: 387 | W34: 0 | X34: Cash | Y34: 81.84 | Z34: 8.72 | AA34: Burgrill-Dine In | AB34: Dine In | AE34: ZQVQWXQQ | AF34: new | AG34: 9717033322 | AK34: 0 | AL34: 0 | AN34: 387 | AV34: 369 | AW34: 9.23 | AX34: 369 | AY34: 9.23 | AZ34: 369
A35: Store 1 | B35: 110027 | C35: Outlet | D35: Burgrill | E35: 45962 | F35: RJ390555 | G35: POS | J35: 45962.773 | K35: Sale | L35: No | M35: 59 | N35: 0 | O35: 0 | P35: 59 | Q35: 0 | R35: 2.96 | S35: 0.04 | T35: 0 | U35: 62 | V35: 62 | W35: 0 | X35: Card | Y35: 15.49 | Z35: 2.14 | AA35: Burgrill-Dine In | AB35: Dine In | AE35: RJFXN3YM | AF35: Burgrill | AG35: 8929758003 | AK35: 0 | AL35: 0 | AM35: 62 | AV35: 59 | AW35: 1.48 | AX35: 59 | AY35: 1.48 | AZ35: 59
A36: Store 1 | B36: 110027 | C36: Outlet | D36: Burgrill | E36: 45962 | F36: RJ390552 | G36: POS | J36: 45962.773 | K36: Sale | L36: No | M36: 507 | N36: 0 | O36: 0 | P36: 507 | Q36: 0 | R36: 25.36 | S36: -0.36 | T36: 0 | U36: 532 | V36: 532 | W36: 0 | X36: Card | Y36: 107.54 | Z36: 12.83 | AA36: Burgrill-Dine In | AB36: Dine In | AE36: RJFXN3YM | AF36: Burgrill | AG36: 8929758003 | AK36: 0 | AL36: 0 | AM36: 532 | AV36: 507 | AW36: 12.68 | AX36: 507 | AY36: 12.68 | AZ36: 507
A37: Store 1 | B37: 110027 | C37: Outlet | D37: Burgrill | E37: 45962 | F37: RJ390548 | G37: POS | J37: 45962.773 | K37: Sale | L37: No | M37: 398 | N37: 0 | O37: 0 | P37: 398 | Q37: 0 | R37: 19.9 | S37: 0.1 | T37: 0 | U37: 418 | V37: 418 | W37: 0 | X37: Card | Y37: 108.44 | Z37: 10.46 | AA37: Burgrill-Dine In | AB37: Dine In | AE37: RJFXN3YM | AF37: Burgrill | AG37: 8929758003 | AK37: 0 | AL37: 0 | AM37: 418 | AV37: 398 | AW37: 9.95 | AX37: 398 | AY37: 9.95 | AZ37: 398
A38: Store 1 | B38: 110027 | C38: Outlet | D38: Burgrill | E38: 45962 | F38: RJ390566 | G38: zomato | H38: 7433349559 | I38: 18528960 | J38: 45962.78 | K38: Sale | L38: No | M38: 349 | N38: -174.5 | O38: 0 | P38: 174.5 | Q38: 32 | R38: 0 | S38: 0 | T38: 0 | U38: 206.5 | V38: 206.5 | W38: 0 | X38: Zomato | Y38: 64.83 | Z38: 4.77 | AA38: Burgrill-Zomato | AB38: Burgrill | AC38: 9559 | AK38: 32 | AL38: 0 | AT38: 206.5 | AZ38: 174.5 | BC38: 32
A39: Store 1 | B39: 110027 | C39: Outlet | D39: Burgrill | E39: 45962 | F39: RJ390567 | G39: zomato | H39: 7431662061 | I39: 18528960 | J39: 45962.79 | K39: Sale | L39: No | M39: 1583.57 | N39: -677.59 | O39: 0 | P39: 905.98 | Q39: 32 | R39: 0 | S39: 0 | T39: 0 | U39: 937.98 | V39: 937.98 | W39: 0 | X39: Zomato | Y39: 288.31 | Z39: 26.97 | AA39: Burgrill-Zomato | AB39: Burgrill | AC39: 2061 | AK39: 32 | AL39: 0 | AT39: 937.98 | AZ39: 905.99 | BC39: 32
A40: Store 1 | B40: 110027 | C40: Outlet | D40: Burgrill | E40: 45962 | F40: RJ390568 | G40: zomato | H40: 7436694056 | I40: 18528960 | J40: 45962.792 | K40: Sale | L40: No | M40: 399 | N40: -75 | O40: 0 | P40: 324 | Q40: 32 | R40: 0 | S40: 0 | T40: 0 | U40: 356 | V40: 356 | W40: 0 | X40: Zomato | Y40: 88.74 | Z40: 4.96 | AA40: Burgrill-Zomato | AB40: Burgrill | AC40: 4056 | AK40: 32 | AL40: 0 | AT40: 356 | AZ40: 324 | BC40: 32
...

Sheet Main
A1: Branch Name | B1: Branch Code | C1: BranchLabels | D1: Business Brand | E1: Business Date | F1: Invoice Number | G1: Order Source | H1: Order_source_1 | I1: Source Order Number | J1: Source Outlet Id | K1: Invoice Date | L1: Date | M1: Day | N1: Month | O1: Hours | P1: Week | Q1: Advance Order | R1: Gross Amount | S1: Discounts | T1: Discount % | U1: Net Amount | V1: Other Charge Amount | W1: Taxes | X1: Rounding | Y1: Total | Z1: Paid Amount | AA1: Payment Modes | AB1: Materials Cost | AC1: Supplies Cost | AD1: Channel | AE1: Channel Label | AF1: Label | AG1: Label | AH1: Session | AI1: Customer Id | AJ1: Customer Name | AK1: Customer Phone | AL1: Customer Tax Id | AM1: Customer State | AN1: Statement Number | AO1: Charges Amount (Initial) | AP1: Charges Amount (Removed) | AQ1: Payment-Card | AR1: Payment-Cash | AS1: Payment-Dineout Pay | AT1: Payment-magicpin | AU1: Payment-Magicpin Pay | AV1: Payment-Paytm | AW1: Payment-Swiggy | AX1: Payment-Zomato | AY1: Payment-Zomato District | AZ1: CGST 2.5% Value | BA1: CGST 2.5% Amount | BB1: SGST 2.5% Value | BC1: SGST 2.5% Amount | BD1: Paid Amount | BE1: Account-Burgrill | BF1: Account-The Sausage Fest | BG1: Consolidated revenue to Burgrill | BH1: Charge-Packing Charges | BI1: Charge-Restaurant Packaging Charges
A2: Store 1 | B2: 110027 | C2: Outlet | D2: Burgrill | E2: 45962 | F2: RJ390531 | G2: zomato | H2: =IF(G2="POS","Direct Sale","Aggregator") -> Aggregator | I2: 7430059910 | J2: 18528960 | K2: 45962.518 | L2: =VALUE(DAY(K2)) -> 1 | M2: =TEXT(K2,"dddd") -> Saturday | N2: =TEXT(K2,"MMMM") -> November | O2: 0.51805556 | P2: =_xlfn.IFS(L2<=7,"Week 1",L2<=15, "Week 2",L2<=23,"Week 3",L2<=30,"Week 4") -> Week 1 | Q2: No | R2: 257 | S2: 0 | T2: =ABS((S2/R2)*100) -> 0 | U2: 257 | V2: 32 | W2: 0 | X2: 0 | Y2: 289 | Z2: 289 | AA2: Zomato | AB2: 52.81 | AC2: 3.92 | AD2: Zomato | AE2: Burgrill | AF2: 9910 | AG2: 9910 | AO2: 32 | AP2: 0 | AX2: 289 | BD2: 289 | BE2: 257 | BG2: =BE2+BF2 -> 257 | BI2: 32
A3: Store 1 | B3: 110027 | C3: Outlet | D3: Burgrill | E3: 45962 | F3: RJ390532 | G3: swiggy | H3: =IF(G3="POS","Direct Sale","Aggregator") -> Aggregator | I3: 220952000000000 | J3: 29811 | K3: 45962.544 | L3: =VALUE(DAY(K3)) -> 1 | M3: =TEXT(K3,"dddd") -> Saturday | N3: =TEXT(K3,"MMMM") -> November | O3: 0.54375 | P3: =_xlfn.IFS(L3<=7,"Week 1",L3<=15, "Week 2",L3<=23,"Week 3",L3<=30,"Week 4") -> Week 1 | Q3: No | R3: 576 | S3: -93.74 | T3: =ABS((S3/R3)*100) -> 16.274306 | U3: 482.26 | V3: 32 | W3: 0 | X3: -0.26 | Y3: 514 | Z3: 514 | AA3: Swiggy | AB3: 126.08 | AC3: 9.76 | AD3: Swiggy | AE3: Burgrill | AF3: 5597 | AG3: 5597 | AO3: 32 | AP3: 0 | AW3: 514 | BD3: 514 | BE3: 482.26 | BG3: =BE3+BF3 -> 482.26 | BH3: 32
A4: Store 1 | B4: 110027 | C4: Outlet | D4: Burgrill | E4: 45962 | F4: RJ390530 | G4: POS | H4: =IF(G4="POS","Direct Sale","Aggregator") -> Direct Sale | K4: 45962.565 | L4: =VALUE(DAY(K4)) -> 1 | M4: =TEXT(K4,"dddd") -> Saturday | N4: =TEXT(K4,"MMMM") -> November | O4: 0.56458333 | P4: =_xlfn.IFS(L4<=7,"Week 1",L4<=15, "Week 2",L4<=23,"Week 3",L4<=30,"Week 4") -> Week 1 | Q4: No | R4: 59 | S4: 0 | T4: =ABS((S4/R4)*100) -> 0 | U4: 59 | V4: 0 | W4: 2.96 | X4: 0.04 | Y4: 62 | Z4: 62 | AA4: Cash | AB4: 15.49 | AC4: 1.96 | AD4: Takeaway | AI4: 4VS4ZNEI | AJ4: vipin | AK4: 9990930244 | AO4: 0 | AP4: 0 | AR4: 62 | AZ4: 59 | BA4: 1.48 | BB4: 59 | BC4: 1.48 | BD4: 62 | BE4: 59 | BG4: =BE4+BF4 -> 59
A5: Store 1 | B5: 110027 | C5: Outlet | D5: Burgrill | E5: 45962 | F5: RJ390529 | G5: POS | H5: =IF(G5="POS","Direct Sale","Aggregator") -> Direct Sale | K5: 45962.565 | L5: =VALUE(DAY(K5)) -> 1 | M5: =TEXT(K5,"dddd") -> Saturday | N5: =TEXT(K5,"MMMM") -> November | O5: 0.56458333 | P5: =_xlfn.IFS(L5<=7,"Week 1",L5<=15, "Week 2",L5<=23,"Week 3",L5<=30,"Week 4") -> Week 1 | Q5: No | R5: 159 | S5: 0 | T5: =ABS((S5/R5)*100) -> 0 | U5: 159 | V5: 0 | W5: 7.96 | X5: 0.04 | Y5: 167 | Z5: 167 | AA5: Card | AB5: 29.83 | AC5: 2.5 | AD5: Burgrill Dine In | AE5: Dine In | AI5: R7ZUEYAL | AJ5: naman | AK5: 9267927604 | AO5: 0 | AP5: 0 | AQ5: 167 | AZ5: 159 | BA5: 3.98 | BB5: 159 | BC5: 3.98 | BD5: 167 | BE5: 159 | BG5: =BE5+BF5 -> 159
A6: Store 1 | B6: 110027 | C6: Outlet | D6: Burgrill | E6: 45962 | F6: RJ390533 | G6: zomato | H6: =IF(G6="POS","Direct Sale","Aggregator") -> Aggregator | I6: 7436034135 | J6: 18528960 | K6: 45962.568 | L6: =VALUE(DAY(K6)) -> 1 | M6: =TEXT(K6,"dddd") -> Saturday | N6: =TEXT(K6,"MMMM") -> November | O6: 0.56805556 | P6: =_xlfn.IFS(L6<=7,"Week 1",L6<=15, "Week 2",L6<=23,"Week 3",L6<=30,"Week 4") -> Week 1 | Q6: No | R6: 418 | S6: -75 | T6: =ABS((S6/R6)*100) -> 17.942584 | U6: 343 | V6: 32 | W6: 0 | X6: 0 | Y6: 375 | Z6: 375 | AA6: Zomato | AB6: 80.87 | AC6: 4.77 | AD6: Zomato | AE6: Burgrill | AF6: 4135 | AG6: 4135 | AO6: 32 | AP6: 0 | AX6: 375 | BD6: 375 | BE6: 343 | BG6: =BE6+BF6 -> 343 | BI6: 32
A7: Store 1 | B7: 110027 | C7: Outlet | D7: Burgrill | E7: 45962 | F7: RJ390537 | G7: zomato | H7: =IF(G7="POS","Direct Sale","Aggregator") -> Aggregator | I7: 7436304288 | J7: 18528960 | K7: 45962.595 | L7: =VALUE(DAY(K7)) -> 1 | M7: =TEXT(K7,"dddd") -> Saturday | N7: =TEXT(K7,"MMMM") -> November | O7: 0.59513889 | P7: =_xlfn.IFS(L7<=7,"Week 1",L7<=15, "Week 2",L7<=23,"Week 3",L7<=30,"Week 4") -> Week 1 | Q7: No | R7: 359 | S7: -75 | T7: =ABS((S7/R7)*100) -> 20.891365 | U7: 284 | V7: 32 | W7: 0 | X7: 0 | Y7: 316 | Z7: 316 | AA7: Zomato | AB7: 77.14 | AC7: 9.82 | AD7: Zomato | AE7: Burgrill | AF7: 4288 | AG7: 4288 | AO7: 32 | AP7: 0 | AX7: 316 | BD7: 316 | BE7: 284 | BG7: =BE7+BF7 -> 284 | BI7: 32
A8: Store 1 | B8: 110027 | C8: Outlet | D8: Burgrill | E8: 45962 | F8: RJ390538 | G8: swiggy | H8: =IF(G8="POS","Direct Sale","Aggregator") -> Aggregator | I8: 220957000000000 | J8: 29811 | K8: 45962.6 | L8: =VALUE(DAY(K8)) -> 1 | M8: =TEXT(K8,"dddd") -> Saturday | N8: =TEXT(K8,"MMMM") -> November | O8: 0.6 | P8: =_xlfn.IFS(L8<=7,"Week 1",L8<=15, "Week 2",L8<=23,"Week 3",L8<=30,"Week 4") -> Week 1 | Q8: No | R8: 508 | S8: -200 | T8: =ABS((S8/R8)*100) -> 39.370079 | U8: 308 | V8: 32 | W8: 0 | X8: 0 | Y8: 340 | Z8: 340 | AA8: Swiggy | AB8: 74.34 | AC8: 3.38 | AD8: Swiggy | AE8: Burgrill | AF8: 4258 | AG8: 4258 | AO8: 32 | AP8: 0 | AW8: 340 | BD8: 340 | BE8: 308 | BG8: =BE8+BF8 -> 308 | BH8: 32
A9: Store 1 | B9: 110027 | C9: Outlet | D9: Burgrill | E9: 45962 | F9: RJ390539 | G9: zomato | H9: =IF(G9="POS","Direct Sale","Aggregator") -> Aggregator | I9: 7436617919 | J9: 18528960 | K9: 45962.612 | L9: =VALUE(DAY(K9)) -> 1 | M9: =TEXT(K9,"dddd") -> Saturday | N9: =TEXT(K9,"MMMM") -> November | O9: 0.61180556 | P9: =_xlfn.IFS(L9<=7,"Week 1",L9<=15, "Week 2",L9<=23,"Week 3",L9<=30,"Week 4") -> Week 1 | Q9: No | R9: 308 | S9: -100 | T9: =ABS((S9/R9)*100) -> 32.467532 | U9: 208 | V9: 32 | W9: 0 | X9: 0 | Y9: 240 | Z9: 240 | AA9: Zomato | AB9: 56.44 | AC9: 10.56 | AD9: Zomato | AE9: Burgrill | AF9: 7919 | AG9: 7919 | AO9: 32 | AP9: 0 | AX9: 240 | BD9: 240 | BE9: 208 | BG9: =BE9+BF9 -> 208 | BI9: 32
A10: Store 1 | B10: 110027 | C10: Outlet | D10: Burgrill | E10: 45962 | F10: RJ390540 | G10: swiggy | H10: =IF(G10="POS","Direct Sale","Aggregator") -> Aggregator | I10: 220958000000000 | J10: 29811 | K10: 45962.617 | L10: =VALUE(DAY(K10)) -> 1 | M10: =TEXT(K10,"dddd") -> Saturday | N10: =TEXT(K10,"MMMM") -> November | O10: 0.61666667 | P10: =_xlfn.IFS(L10<=7,"Week 1",L10<=15, "Week 2",L10<=23,"Week 3",L10<=30,"Week 4") -> Week 1 | Q10: No | R10: 508 | S10: -93.74 | T10: =ABS((S10/R10)*100) -> 18.452756 | U10: 414.26 | V10: 32 | W10: 0 | X10: -0.26 | Y10: 446 | Z10: 446 | AA10: Swiggy | AB10: 94.86 | AC10: 13.74 | AD10: Swiggy | AE10: Burgrill | AF10: 7113 | AG10: 7113 | AO10: 32 | AP10: 0 | AW10: 446 | BD10: 446 | BE10: 414.26 | BG10: =BE10+BF10 -> 414.26 | BH10: 32
A11: Store 1 | B11: 110027 | C11: Outlet | D11: Burgrill | E11: 45962 | F11: RJ390541 | G11: swiggy | H11: =IF(G11="POS","Direct Sale","Aggregator") -> Aggregator | I11: 220959000000000 | J11: 29811 | K11: 45962.624 | L11: =VALUE(DAY(K11)) -> 1 | M11: =TEXT(K11,"dddd") -> Saturday | N11: =TEXT(K11,"MMMM") -> November | O11: 0.62430556 | P11: =_xlfn.IFS(L11<=7,"Week 1",L11<=15, "Week 2",L11<=23,"Week 3",L11<=30,"Week 4") -> Week 1 | Q11: No | R11: 393.28 | S11: -93.75 | T11: =ABS((S11/R11)*100) -> 23.837978 | U11: 299.53 | V11: 32 | W11: 0 | X11: 0.47 | Y11: 332 | Z11: 332 | AA11: Swiggy | AB11: 91.25 | AC11: 5.79 | AD11: Swiggy | AE11: Burgrill | AF11: 124 | AG11: 124 | AO11: 32 | AP11: 0 | AW11: 332 | BD11: 332 | BE11: 299.53 | BG11: =BE11+BF11 -> 299.53 | BH11: 32
A12: Store 1 | B12: 110027 | C12: Outlet | D12: Burgrill | E12: 45962 | F12: RJ390542 | G12: swiggy | H12: =IF(G12="POS","Direct Sale","Aggregator") -> Aggregator | I12: 220959000000000 | J12: 29811 | K12: 45962.626 | L12: =VALUE(DAY(K12)) -> 1 | M12: =TEXT(K12,"dddd") -> Saturday | N12: =TEXT(K12,"MMMM") -> November | O12: 0.62569444 | P12: =_xlfn.IFS(L12<=7,"Week 1",L12<=15, "Week 2",L12<=23,"Week 3",L12<=30,"Week 4") -> Week 1 | Q12: No | R12: 268 | S12: -93.75 | T12: =ABS((S12/R12)*100) -> 34.981343 | U12: 174.25 | V12: 32 | W12: 0 | X12: -0.25 | Y12: 206 | Z12: 206 | AA12: Swiggy | AB12: 49.33 | AC12: 7.46 | AD12: Swiggy | AE12: Burgrill | AF12: 4459 | AG12: 4459 | AO12: 32 | AP12: 0 | AW12: 206 | BD12: 206 | BE12: 174.25 | BG12: =BE12+BF12 -> 174.25 | BH12: 32
A13: Store 1 | B13: 110027 | C13: Outlet | D13: Burgrill | E13: 45962 | F13: RJ390543 | G13: zomato | H13: =IF(G13="POS","Direct Sale","Aggregator") -> Aggregator | I13: 7435937715 | J13: 18528960 | K13: 45962.64 | L13: =VALUE(DAY(K13)) -> 1 | M13: =TEXT(K13,"dddd") -> Saturday | N13: =TEXT(K13,"MMMM") -> November | O13: 0.64027778 | P13: =_xlfn.IFS(L13<=7,"Week 1",L13<=15, "Week 2",L13<=23,"Week 3",L13<=30,"Week 4") -> Week 1 | Q13: No | R13: 698 | S13: -349 | T13: =ABS((S13/R13)*100) -> 50 | U13: 349 | V13: 32 | W13: 0 | X13: 0 | Y13: 381 | Z13: 381 | AA13: Zomato | AB13: 129.66 | AC13: 9.54 | AD13: Zomato | AE13: Burgrill | AF13: 7715 | AG13: 7715 | AO13: 32 | AP13: 0 | AX13: 381 | BD13: 381 | BE13: 349 | BG13: =BE13+BF13 -> 349 | BI13: 32
A14: Store 1 | B14: 110027 | C14: Outlet | D14: Burgrill | E14: 45962 | F14: RJ390544 | G14: zomato | H14: =IF(G14="POS","Direct Sale","Aggregator") -> Aggregator | I14: 7435794679 | J14: 18528960 | K14: 45962.65 | L14: =VALUE(DAY(K14)) -> 1 | M14: =TEXT(K14,"dddd") -> Saturday | N14: =TEXT(K14,"MMMM") -> November | O14: 0.65 | P14: =_xlfn.IFS(L14<=7,"Week 1",L14<=15, "Week 2",L14<=23,"Week 3",L14<=30,"Week 4") -> Week 1 | Q14: No | R14: 574.66 | S14: -199.5 | T14: =ABS((S14/R14)*100) -> 34.71618 | U14: 375.16 | V14: 32 | W14: 0 | X14: 0 | Y14: 407.16 | Z14: 407.16 | AA14: Zomato | AB14: 99.34 | AC14: 4.06 | AD14: Zomato | AE14: Burgrill | AF14: 4679 | AG14: 4679 | AO14: 32 | AP14: 0 | AX14: 407.16 | BD14: 407.16 | BE14: 375.16 | BG14: =BE14+BF14 -> 375.16 | BI14: 32
A15: Store 1 | B15: 110027 | C15: Outlet | D15: Burgrill | E15: 45962 | F15: RJ390545 | G15: swiggy | H15: =IF(G15="POS","Direct Sale","Aggregator") -> Aggregator | I15: 220962000000000 | J15: 29811 | K15: 45962.656 | L15: =VALUE(DAY(K15)) -> 1 | M15: =TEXT(K15,"dddd") -> Saturday | N15: =TEXT(K15,"MMMM") -> November | O15: 0.65625 | P15: =_xlfn.IFS(L15<=7,"Week 1",L15<=15, "Week 2",L15<=23,"Week 3",L15<=30,"Week 4") -> Week 1 | Q15: No | R15: 258 | S15: -93.75 | T15: =ABS((S15/R15)*100) -> 36.337209 | U15: 164.25 | V15: 32 | W15: 0 | X15: -0.25 | Y15: 196 | Z15: 196 | AA15: Swiggy | AB15: 48.54 | AC15: 7.02 | AD15: Swiggy | AE15: Burgrill | AF15: 3213 | AG15: 3213 | AO15: 32 | AP15: 0 | AW15: 196 | BD15: 196 | BE15: 164.25 | BG15: =BE15+BF15 -> 164.25 | BH15: 32
A16: Store 1 | B16: 110027 | C16: Outlet | D16: Burgrill | E16: 45962 | F16: RJ390534 | G16: POS | H16: =IF(G16="POS","Direct Sale","Aggregator") -> Direct Sale | K16: 45962.669 | L16: =VALUE(DAY(K16)) -> 1 | M16: =TEXT(K16,"dddd") -> Saturday | N16: =TEXT(K16,"MMMM") -> November | O16: 0.66875 | P16: =_xlfn.IFS(L16<=7,"Week 1",L16<=15, "Week 2",L16<=23,"Week 3",L16<=30,"Week 4") -> Week 1 | Q16: No | R16: 288 | S16: 0 | T16: =ABS((S16/R16)*100) -> 0 | U16: 288 | V16: 0 | W16: 14.4 | X16: -0.4 | Y16: 302 | Z16: 302 | AA16: Card | AB16: 68.99 | AC16: 3.92 | AD16: Burgrill Dine In | AE16: Dine In | AI16: RJFXN3YM | AJ16: Burgrill | AK16: 8929758003 | AO16: 0 | AP16: 0 | AQ16: 302 | AZ16: 288 | BA16: 7.2 | BB16: 288 | BC16: 7.2 | BD16: 302 | BE16: 288 | BG16: =BE16+BF16 -> 288
A17: Store 1 | B17: 110027 | C17: Outlet | D17: Burgrill | E17: 45962 | F17: RJ390535 | G17: POS | H17: =IF(G17="POS","Direct Sale","Aggregator") -> Direct Sale | K17: 45962.669 | L17: =VALUE(DAY(K17)) -> 1 | M17: =TEXT(K17,"dddd") -> Saturday | N17: =TEXT(K17,"MMMM") -> November | O17: 0.66944444 | P17: =_xlfn.IFS(L17<=7,"Week 1",L17<=15, "Week 2",L17<=23,"Week 3",L17<=30,"Week 4") -> Week 1 | Q17: No | R17: 356 | S17: 0 | T17: =ABS((S17/R17)*100) -> 0 | U17: 356 | V17: 0 | W17: 17.8 | X17: 0.2 | Y17: 374 | Z17: 374 | AA17: Card | AB17: 100.44 | AC17: 8.16 | AD17: Burgrill Dine In | AE17: Dine In | AI17: BCTCUL8A | AJ17: ms | AK17: 8171020359 | AO17: 0 | AP17: 0 | AQ17: 374 | AZ17: 356 | BA17: 8.9 | BB17: 356 | BC17: 8.9 | BD17: 374 | BE17: 356 | BG17: =BE17+BF17 -> 356
A18: Store 1 | B18: 110027 | C18: Outlet | D18: Burgrill | E18: 45962 | F18: RJ390536 | G18: POS | H18: =IF(G18="POS","Direct Sale","Aggregator") -> Direct Sale | K18: 45962.669 | L18: =VALUE(DAY(K18)) -> 1 | M18: =TEXT(K18,"dddd") -> Saturday | N18: =TEXT(K18,"MMMM") -> November | O18: 0.66944444 | P18: =_xlfn.IFS(L18<=7,"Week 1",L18<=15, "Week 2",L18<=23,"Week 3",L18<=30,"Week 4") -> Week 1 | Q18: No | R18: 66.66 | S18: 0 | T18: =ABS((S18/R18)*100) -> 0 | U18: 66.66 | V18: 0 | W18: 3.34 | X18: 0 | Y18: 70 | Z18: 70 | AA18: Card | AB18: 25 | AC18: 0 | AD18: Burgrill Dine In | AE18: Dine In | AI18: RJFXN3YM | AJ18: Burgrill | AK18: 8929758003 | AO18: 0 | AP18: 0 | AQ18: 70 | AZ18: 66.66 | BA18: 1.67 | BB18: 66.66 | BC18: 1.67 | BD18: 70 | BE18: 66.66 | BG18: =BE18+BF18 -> 66.66
A19: Store 1 | B19: 110027 | C19: Outlet | D19: Burgrill | E19: 45962 | F19: RJ390546 | G19: swiggy | H19: =IF(G19="POS","Direct Sale","Aggregator") -> Aggregator | I19: 220963000000000 | J19: 29811 | K19: 45962.676 | L19: =VALUE(DAY(K19)) -> 1 | M19: =TEXT(K19,"dddd") -> Saturday | N19: =TEXT(K19,"MMMM") -> November | O19: 0.67638889 | P19: =_xlfn.IFS(L19<=7,"Week 1",L19<=15, "Week 2",L19<=23,"Week 3",L19<=30,"Week 4") -> Week 1 | Q19: No | R19: 545 | S19: -130 | T19: =ABS((S19/R19)*100) -> 23.853211 | U19: 415 | V19: 32 | W19: 0 | X19: 0 | Y19: 447 | Z19: 447 | AA19: Swiggy | AB19: 99.73 | AC19: 9.8 | AD19: Swiggy | AE19: Burgrill | AF19: 5595 | AG19: 5595 | AO19: 32 | AP19: 0 | AW19: 447 | BD19: 447 | BE19: 415 | BG19: =BE19+BF19 -> 415 | BH19: 32
A20: Store 1 | B20: 110027 | C20: Outlet | D20: Burgrill | E20: 45962 | F20: RJ390547 | G20: swiggy | H20: =IF(G20="POS","Direct Sale","Aggregator") -> Aggregator | I20: 220963000000000 | J20: 29811 | K20: 45962.677 | L20: =VALUE(DAY(K20)) -> 1 | M20: =TEXT(K20,"dddd") -> Saturday | N20: =TEXT(K20,"MMMM") -> November | O20: 0.67708333 | P20: =_xlfn.IFS(L20<=7,"Week 1",L20<=15, "Week 2",L20<=23,"Week 3",L20<=30,"Week 4") -> Week 1 | Q20: No | R20: 395 | S20: -74.99 | T20: =ABS((S20/R20)*100) -> 18.98481 | U20: 320.01 | V20: 32 | W20: 0 | X20: -0.01 | Y20: 352 | Z20: 352 | AA20: Swiggy | AB20: 74.43 | AC20: 8.88 | AD20: Swiggy | AE20: Burgrill | AF20: 5423 | AG20: 5423 | AO20: 32 | AP20: 0 | AW20: 352 | BD20: 352 | BE20: 320.01 | BG20: =BE20+BF20 -> 320.01 | BH20: 32
A21: Store 1 | B21: 110027 | C21: Outlet | D21: Burgrill | E21: 45962 | F21: RJ390549 | G21: POS | H21: =IF(G21="POS","Direct Sale","Aggregator") -> Direct Sale | K21: 45962.697 | L21: =VALUE(DAY(K21)) -> 1 | M21: =TEXT(K21,"dddd") -> Saturday | N21: =TEXT(K21,"MMMM") -> November | O21: 0.69652778 | P21: =_xlfn.IFS(L21<=7,"Week 1",L21<=15, "Week 2",L21<=23,"Week 3",L21<=30,"Week 4") -> Week 1 | Q21: No | R21: 159 | S21: 0 | T21: =ABS((S21/R21)*100) -> 0 | U21: 159 | V21: 0 | W21: 7.96 | X21: 0.04 | Y21: 167 | Z21: 167 | AA21: Cash | AB21: 29.83 | AC21: 2.5 | AD21: Burgrill Dine In | AE21: Dine In | AI21: E9WZ2UG5 | AJ21: sidhi | AK21: 7817653551 | AO21: 0 | AP21: 0 | AR21: 167 | AZ21: 159 | BA21: 3.98 | BB21: 159 | BC21: 3.98 | BD21: 167 | BE21: 159 | BG21: =BE21+BF21 -> 159
A22: Store 1 | B22: 110027 | C22: Outlet | D22: Burgrill | E22: 45962 | F22: RJ390550 | G22: swiggy | H22: =IF(G22="POS","Direct Sale","Aggregator") -> Aggregator | I22: 220966000000000 | J22: 29811 | K22: 45962.702 | L22: =VALUE(DAY(K22)) -> 1 | M22: =TEXT(K22,"dddd") -> Saturday | N22: =TEXT(K22,"MMMM") -> November | O22: 0.70208333 | P22: =_xlfn.IFS(L22<=7,"Week 1",L22<=15, "Week 2",L22<=23,"Week 3",L22<=30,"Week 4") -> Week 1 | Q22: No | R22: 646 | S22: -93.75 | T22: =ABS((S22/R22)*100) -> 14.512384 | U22: 552.25 | V22: 32 | W22: 0 | X22: -0.25 | Y22: 584 | Z22: 584 | AA22: Swiggy | AB22: 150.41 | AC22: 14.78 | AD22: Swiggy | AE22: Burgrill | AF22: 379 | AG22: 379 | AO22: 32 | AP22: 0 | AW22: 584 | BD22: 584 | BE22: 552.25 | BG22: =BE22+BF22 -> 552.25 | BH22: 32
A23: Store 1 | B23: 110027 | C23: Outlet | D23: Burgrill | E23: 45962 | F23: RJ390551 | G23: POS | H23: =IF(G23="POS","Direct Sale","Aggregator") -> Direct Sale | K23: 45962.706 | L23: =VALUE(DAY(K23)) -> 1 | M23: =TEXT(K23,"dddd") -> Saturday | N23: =TEXT(K23,"MMMM") -> November | O23: 0.70555556 | P23: =_xlfn.IFS(L23<=7,"Week 1",L23<=15, "Week 2",L23<=23,"Week 3",L23<=30,"Week 4") -> Week 1 | Q23: No | R23: 369 | S23: 0 | T23: =ABS((S23/R23)*100) -> 0 | U23: 369 | V23: 0 | W23: 18.46 | X23: -0.46 | Y23: 387 | Z23: 387 | AA23: Cash | AB23: 99.73 | AC23: 8.72 | AD23: Burgrill Dine In | AE23: Dine In | AI23: GIDIRMS3 | AJ23: hare krishna | AK23: 9999669771 | AO23: 0 | AP23: 0 | AR23: 387 | AZ23: 369 | BA23: 9.23 | BB23: 369 | BC23: 9.23 | BD23: 387 | BE23: 369 | BG23: =BE23+BF23 -> 369
A24: Store 1 | B24: 110027 | C24: Outlet | D24: Burgrill | E24: 45962 | F24: RJ390554 | G24: zomato | H24: =IF(G24="POS","Direct Sale","Aggregator") -> Aggregator | I24: 7437673579 | J24: 18528960 | K24: 45962.71 | L24: =VALUE(DAY(K24)) -> 1 | M24: =TEXT(K24,"dddd") -> Saturday | N24: =TEXT(K24,"MMMM") -> November | O24: 0.70972222 | P24: =_xlfn.IFS(L24<=7,"Week 1",L24<=15, "Week 2",L24<=23,"Week 3",L24<=30,"Week 4") -> Week 1 | Q24: No | R24: 663.66 | S24: -248.9 | T24: =ABS((S24/R24)*100) -> 37.504144 | U24: 414.76 | V24: 32 | W24: 0 | X24: 0 | Y24: 446.76 | Z24: 446.76 | AA24: Zomato | AB24: 135.43 | AC24: 10.95 | AD24: Zomato | AE24: Burgrill | AF24: 3579 | AG24: 3579 | AO24: 32 | AP24: 0 | AX24: 446.76 | BD24: 446.76 | BE24: 414.76 | BG24: =BE24+BF24 -> 414.76 | BI24: 32
A25: Store 1 | B25: 110027 | C25: Outlet | D25: Burgrill | E25: 45962 | F25: RJ390558 | G25: swiggy | H25: =IF(G25="POS","Direct Sale","Aggregator") -> Aggregator | I25: 220968000000000 | J25: 29811 | K25: 45962.729 | L25: =VALUE(DAY(K25)) -> 1 | M25: =TEXT(K25,"dddd") -> Saturday | N25: =TEXT(K25,"MMMM") -> November | O25: 0.72916667 | P25: =_xlfn.IFS(L25<=7,"Week 1",L25<=15, "Week 2",L25<=23,"Week 3",L25<=30,"Week 4") -> Week 1 | Q25: No | R25: 318 | S25: -93.75 | T25: =ABS((S25/R25)*100) -> 29.481132 | U25: 224.25 | V25: 32 | W25: 0 | X25: -0.25 | Y25: 256 | Z25: 256 | AA25: Swiggy | AB25: 70.61 | AC25: 4.77 | AD25: Swiggy | AE25: Burgrill | AF25: 9697 | AG25: 9697 | AO25: 32 | AP25: 0 | AW25: 256 | BD25: 256 | BE25: 224.25 | BG25: =BE25+BF25 -> 224.25 | BH25: 32
A26: Store 1 | B26: 110027 | C26: Outlet | D26: Burgrill | E26: 45962 | F26: RJ390559 | G26: swiggy | H26: =IF(G26="POS","Direct Sale","Aggregator") -> Aggregator | I26: 220968000000000 | J26: 29811 | K26: 45962.731 | L26: =VALUE(DAY(K26)) -> 1 | M26: =TEXT(K26,"dddd") -> Saturday | N26: =TEXT(K26,"MMMM") -> November | O26: 0.73055556 | P26: =_xlfn.IFS(L26<=7,"Week 1",L26<=15, "Week 2",L26<=23,"Week 3",L26<=30,"Week 4") -> Week 1 | Q26: No | R26: 178 | S26: -20 | T26: =ABS((S26/R26)*100) -> 11.235955 | U26: 158 | V26: 32 | W26: 0 | X26: 0 | Y26: 190 | Z26: 190 | AA26: Swiggy | AB26: 37.92 | AC26: 1.96 | AD26: Swiggy | AE26: Burgrill | AF26: 6720 | AG26: 6720 | AO26: 32 | AP26: 0 | AW26: 190 | BD26: 190 | BE26: 158 | BG26: =BE26+BF26 -> 158 | BH26: 32
A27: Store 1 | B27: 110027 | C27: Outlet | D27: Burgrill | E27: 45962 | F27: RJ390560 | G27: zomato | H27: =IF(G27="POS","Direct Sale","Aggregator") -> Aggregator | I27: 7431959854 | J27: 18528960 | K27: 45962.74 | L27: =VALUE(DAY(K27)) -> 1 | M27: =TEXT(K27,"dddd") -> Saturday | N27: =TEXT(K27,"MMMM") -> November | O27: 0.73958333 | P27: =_xlfn.IFS(L27<=7,"Week 1",L27<=15, "Week 2",L27<=23,"Week 3",L27<=30,"Week 4") -> Week 1 | Q27: No | R27: 1036 | S27: 0 | T27: =ABS((S27/R27)*100) -> 0 | U27: 1036 | V27: 32 | W27: 0 | X27: 0 | Y27: 1068 | Z27: 1068 | AA27: Zomato | AB27: 233.97 | AC27: 19.36 | AD27: Zomato | AE27: Burgrill | AF27: 9854 | AG27: 9854 | AO27: 32 | AP27: 0 | AX27: 1068 | BD27: 1068 | BE27: 1036 | BG27: =BE27+BF27 -> 1036 | BI27: 32
A28: Store 1 | B28: 110027 | C28: Outlet | D28: Burgrill | E28: 45962 | F28: RJ390564 | G28: POS | H28: =IF(G28="POS","Direct Sale","Aggregator") -> Direct Sale | K28: 45962.772 | L28: =VALUE(DAY(K28)) -> 1 | M28: =TEXT(K28,"dddd") -> Saturday | N28: =TEXT(K28,"MMMM") -> November | O28: 0.77152778 | P28: =_xlfn.IFS(L28<=7,"Week 1",L28<=15, "Week 2",L28<=23,"Week 3",L28<=30,"Week 4") -> Week 1 | Q28: No | R28: 198 | S28: 0 | T28: =ABS((S28/R28)*100) -> 0 | U28: 198 | V28: 0 | W28: 9.9 | X28: 0.1 | Y28: 208 | Z28: 208 | AA28: Cash | AB28: 48.85 | AC28: 3.92 | AD28: Burgrill Dine In | AE28: Dine In | AI28: RJFXN3YM | AJ28: Burgrill | AK28: 8929758003 | AO28: 0 | AP28: 0 | AR28: 208 | AZ28: 198 | BA28: 4.95 | BB28: 198 | BC28: 4.95 | BD28: 208 | BE28: 198 | BG28: =BE28+BF28 -> 198
A29: Store 1 | B29: 110027 | C29: Outlet | D29: Burgrill | E29: 45962 | F29: RJ390563 | G29: POS | H29: =IF(G29="POS","Direct Sale","Aggregator") -> Direct Sale | K29: 45962.772 | L29: =VALUE(DAY(K29)) -> 1 | M29: =TEXT(K29,"dddd") -> Saturday | N29: =TEXT(K29,"MMMM") -> November | O29: 0.77152778 | P29: =_xlfn.IFS(L29<=7,"Week 1",L29<=15, "Week 2",L29<=23,"Week 3",L29<=30,"Week 4") -> Week 1 | Q29: No | R29: 217 | S29: -15 | T29: =ABS((S29/R29)*100) -> 6.9124424 | U29: 202 | V29: 0 | W29: 10.1 | X29: -0.1 | Y29: 212 | Z29: 212 | AA29: Cash,Card | AB29: 56.03 | AC29: 5.88 | AD29: Takeaway | AI29: I8Y3EPU8 | AJ29: shivam | AK29: 9810206362 | AO29: 0 | AP29: 0 | AQ29: 12 | AR29: 200 | AZ29: 202 | BA29: 5.05 | BB29: 202 | BC29: 5.05 | BD29: 212 | BE29: 202 | BG29: =BE29+BF29 -> 202
A30: Store 1 | B30: 110027 | C30: Outlet | D30: Burgrill | E30: 45962 | F30: RJ390562 | G30: POS | H30: =IF(G30="POS","Direct Sale","Aggregator") -> Direct Sale | K30: 45962.772 | L30: =VALUE(DAY(K30)) -> 1 | M30: =TEXT(K30,"dddd") -> Saturday | N30: =TEXT(K30,"MMMM") -> November | O30: 0.77222222 | P30: =_xlfn.IFS(L30<=7,"Week 1",L30<=15, "Week 2",L30<=23,"Week 3",L30<=30,"Week 4") -> Week 1 | Q30: No | R30: 356 | S30: 0 | T30: =ABS((S30/R30)*100) -> 0 | U30: 356 | V30: 0 | W30: 17.8 | X30: 0.2 | Y30: 374 | Z30: 374 | AA30: Card | AB30: 97.33 | AC30: 8.16 | AD30: Burgrill Dine In | AE30: Dine In | AI30: RJFXN3YM | AJ30: Burgrill | AK30: 8929758003 | AO30: 0 | AP30: 0 | AQ30: 374 | AZ30: 356 | BA30: 8.9 | BB30: 356 | BC30: 8.9 | BD30: 374 | BE30: 356 | BG30: =BE30+BF30 -> 356
A31: Store 1 | B31: 110027 | C31: Outlet | D31: Burgrill | E31: 45962 | F31: RJ390561 | G31: POS | H31: =IF(G31="POS","Direct Sale","Aggregator") -> Direct Sale | K31: 45962.772 | L31: =VALUE(DAY(K31)) -> 1 | M31: =TEXT(K31,"dddd") -> Saturday | N31: =TEXT(K31,"MMMM") -> November | O31: 0.77222222 | P31: =_xlfn.IFS(L31<=7,"Week 1",L31<=15, "Week 2",L31<=23,"Week 3",L31<=30,"Week 4") -> Week 1 | Q31: No | R31: 348 | S31: 0 | T31: =ABS((S31/R31)*100) -> 0 | U31: 348 | V31: 0 | W31: 17.4 | X31: -0.4 | Y31: 365 | Z31: 365 | AA31: Card | AB31: 97.24 | AC31: 4.52 | AD31: Burgrill Dine In | AE31: Dine In | AI31: RJFXN3YM | AJ31: Burgrill | AK31: 8929758003 | AO31: 0 | AP31: 0 | AQ31: 365 | AZ31: 348 | BA31: 8.7 | BB31: 348 | BC31: 8.7 | BD31: 365 | BE31: 348 | BG31: =BE31+BF31 -> 348
A32: Store 1 | B32: 110027 | C32: Outlet | D32: Burgrill | E32: 45962 | F32: RJ390557 | G32: POS | H32: =IF(G32="POS","Direct Sale","Aggregator") -> Direct Sale | K32: 45962.772 | L32: =VALUE(DAY(K32)) -> 1 | M32: =TEXT(K32,"dddd") -> Saturday | N32: =TEXT(K32,"MMMM") -> November | O32: 0.77222222 | P32: =_xlfn.IFS(L32<=7,"Week 1",L32<=15, "Week 2",L32<=23,"Week 3",L32<=30,"Week 4") -> Week 1 | Q32: No | R32: 597 | S32: 0 | T32: =ABS((S32/R32)*100) -> 0 | U32: 597 | V32: 0 | W32: 29.86 | X32: 0.14 | Y32: 627 | Z32: 627 | AA32: Card | AB32: 142.23 | AC32: 7.68 | AD32: Burgrill Dine In | AE32: Dine In | AI32: MJHTLH2P | AJ32: asveed | AK32: 8287834046 | AO32: 0 | AP32: 0 | AQ32: 627 | AZ32: 597 | BA32: 14.93 | BB32: 597 | BC32: 14.93 | BD32: 627 | BE32: 597 | BG32: =BE32+BF32 -> 597
A33: Store 1 | B33: 110027 | C33: Outlet | D33: Burgrill | E33: 45962 | F33: RJ390556 | G33: POS | H33: =IF(G33="POS","Direct Sale","Aggregator") -> Direct Sale | K33: 45962.773 | L33: =VALUE(DAY(K33)) -> 1 | M33: =TEXT(K33,"dddd") -> Saturday | N33: =TEXT(K33,"MMMM") -> November | O33: 0.77291667 | P33: =_xlfn.IFS(L33<=7,"Week 1",L33<=15, "Week 2",L33<=23,"Week 3",L33<=30,"Week 4") -> Week 1 | Q33: No | R33: 594.1 | S33: 0 | T33: =ABS((S33/R33)*100) -> 0 | U33: 594.1 | V33: 0 | W33: 29.7 | X33: 0.2 | Y33: 624 | Z33: 624 | AA33: Cash,Card | AB33: 171.65 | AC33: 8.86 | AD33: Burgrill Dine In | AE33: Dine In | AI33: RJFXN3YM | AJ33: Burgrill | AK33: 8929758003 | AO33: 0 | AP33: 0 | AQ33: 124 | AR33: 500 | AZ33: 594.1 | BA33: 14.85 | BB33: 594.1 | BC33: 14.85 | BD33: 624 | BE33: 594.1 | BG33: =BE33+BF33 -> 594.1
A34: Store 1 | B34: 110027 | C34: Outlet | D34: Burgrill | E34: 45962 | F34: RJ390553 | G34: POS | H34: =IF(G34="POS","Direct Sale","Aggregator") -> Direct Sale | K34: 45962.773 | L34: =VALUE(DAY(K34)) -> 1 | M34: =TEXT(K34,"dddd") -> Saturday | N34: =TEXT(K34,"MMMM") -> November | O34: 0.77291667 | P34: =_xlfn.IFS(L34<=7,"Week 1",L34<=15, "Week 2",L34<=23,"Week 3",L34<=30,"Week 4") -> Week 1 | Q34: No | R34: 369 | S34: 0 | T34: =ABS((S34/R34)*100) -> 0 | U34: 369 | V34: 0 | W34: 18.46 | X34: -0.46 | Y34: 387 | Z34: 387 | AA34: Cash | AB34: 81.84 | AC34: 8.72 | AD34: Burgrill Dine In | AE34: Dine In | AI34: ZQVQWXQQ | AJ34: new | AK34: 9717033322 | AO34: 0 | AP34: 0 | AR34: 387 | AZ34: 369 | BA34: 9.23 | BB34: 369 | BC34: 9.23 | BD34: 387 | BE34: 369 | BG34: =BE34+BF34 -> 369
A35: Store 1 | B35: 110027 | C35: Outlet | D35: Burgrill | E35: 45962 | F35: RJ390555 | G35: POS | H35: =IF(G35="POS","Direct Sale","Aggregator") -> Direct Sale | K35: 45962.773 | L35: =VALUE(DAY(K35)) -> 1 | M35: =TEXT(K35,"dddd") -> Saturday | N35: =TEXT(K35,"MMMM") -> November | O35: 0.77291667 | P35: =_xlfn.IFS(L35<=7,"Week 1",L35<=15, "Week 2",L35<=23,"Week 3",L35<=30,"Week 4") -> Week 1 | Q35: No | R35: 59 | S35: 0 | T35: =ABS((S35/R35)*100) -> 0 | U35: 59 | V35: 0 | W35: 2.96 | X35: 0.04 | Y35: 62 | Z35: 62 | AA35: Card | AB35: 15.49 | AC35: 2.14 | AD35: Burgrill Dine In | AE35: Dine In | AI35: RJFXN3YM | AJ35: Burgrill | AK35: 8929758003 | AO35: 0 | AP35: 0 | AQ35: 62 | AZ35: 59 | BA35: 1.48 | BB35: 59 | BC35: 1.48 | BD35: 62 | BE35: 59 | BG35: =BE35+BF35 -> 59
A36: Store 1 | B36: 110027 | C36: Outlet | D36: Burgrill | E36: 45962 | F36: RJ390552 | G36: POS | H36: =IF(G36="POS","Direct Sale","Aggregator") -> Direct Sale | K36: 45962.773 | L36: =VALUE(DAY(K36)) -> 1 | M36: =TEXT(K36,"dddd") -> Saturday | N36: =TEXT(K36,"MMMM") -> November | O36: 0.77291667 | P36: =_xlfn.IFS(L36<=7,"Week 1",L36<=15, "Week 2",L36<=23,"Week 3",L36<=30,"Week 4") -> Week 1 | Q36: No | R36: 507 | S36: 0 | T36: =ABS((S36/R36)*100) -> 0 | U36: 507 | V36: 0 | W36: 25.36 | X36: -0.36 | Y36: 532 | Z36: 532 | AA36: Card | AB36: 107.54 | AC36: 12.83 | AD36: Burgrill Dine In | AE36: Dine In | AI36: RJFXN3YM | AJ36: Burgrill | AK36: 8929758003 | AO36: 0 | AP36: 0 | AQ36: 532 | AZ36: 507 | BA36: 12.68 | BB36: 507 | BC36: 12.68 | BD36: 532 | BE36: 507 | BG36: =BE36+BF36 -> 507
A37: Store 1 | B37: 110027 | C37: Outlet | D37: Burgrill | E37: 45962 | F37: RJ390548 | G37: POS | H37: =IF(G37="POS","Direct Sale","Aggregator") -> Direct Sale | K37: 45962.773 | L37: =VALUE(DAY(K37)) -> 1 | M37: =TEXT(K37,"dddd") -> Saturday | N37: =TEXT(K37,"MMMM") -> November | O37: 0.77291667 | P37: =_xlfn.IFS(L37<=7,"Week 1",L37<=15, "Week 2",L37<=23,"Week 3",L37<=30,"Week 4") -> Week 1 | Q37: No | R37: 398 | S37: 0 | T37: =ABS((S37/R37)*100) -> 0 | U37: 398 | V37: 0 | W37: 19.9 | X37: 0.1 | Y37: 418 | Z37: 418 | AA37: Card | AB37: 108.44 | AC37: 10.46 | AD37: Burgrill Dine In | AE37: Dine In | AI37: RJFXN3YM | AJ37: Burgrill | AK37: 8929758003 | AO37: 0 | AP37: 0 | AQ37: 418 | AZ37: 398 | BA37: 9.95 | BB37: 398 | BC37: 9.95 | BD37: 418 | BE37: 398 | BG37: =BE37+BF37 -> 398
A38: Store 1 | B38: 110027 | C38: Outlet | D38: Burgrill | E38: 45962 | F38: RJ390566 | G38: zomato | H38: =IF(G38="POS","Direct Sale","Aggregator") -> Aggregator | I38: 7433349559 | J38: 18528960 | K38: 45962.78 | L38: =VALUE(DAY(K38)) -> 1 | M38: =TEXT(K38,"dddd") -> Saturday | N38: =TEXT(K38,"MMMM") -> November | O38: 0.77986111 | P38: =_xlfn.IFS(L38<=7,"Week 1",L38<=15, "Week 2",L38<=23,"Week 3",L38<=30,"Week 4") -> Week 1 | Q38: No | R38: 349 | S38: -174.5 | T38: =ABS((S38/R38)*100) -> 50 | U38: 174.5 | V38: 32 | W38: 0 | X38: 0 | Y38: 206.5 | Z38: 206.5 | AA38: Zomato | AB38: 64.83 | AC38: 4.77 | AD38: Zomato | AE38: Burgrill | AF38: 9559 | AG38: 9559 | AO38: 32 | AP38: 0 | AX38: 206.5 | BD38: 206.5 | BE38: 174.5 | BG38: =BE38+BF38 -> 174.5 | BI38: 32
A39: Store 1 | B39: 110027 | C39: Outlet | D39: Burgrill | E39: 45962 | F39: RJ390567 | G39: zomato | H39: =IF(G39="POS","Direct Sale","Aggregator") -> Aggregator | I39: 7431662061 | J39: 18528960 | K39: 45962.79 | L39: =VALUE(DAY(K39)) -> 1 | M39: =TEXT(K39,"dddd") -> Saturday | N39: =TEXT(K39,"MMMM") -> November | O39: 0.78958333 | P39: =_xlfn.IFS(L39<=7,"Week 1",L39<=15, "Week 2",L39<=23,"Week 3",L39<=30,"Week 4") -> Week 1 | Q39: No | R39: 1583.57 | S39: -677.59 | T39: =ABS((S39/R39)*100) -> 42.788762 | U39: 905.98 | V39: 32 | W39: 0 | X39: 0 | Y39: 937.98 | Z39: 937.98 | AA39: Zomato | AB39: 288.31 | AC39: 26.97 | AD39: Zomato | AE39: Burgrill | AF39: 2061 | AG39: 2061 | AO39: 32 | AP39: 0 | AX39: 937.98 | BD39: 937.98 | BE39: 905.99 | BG39: =BE39+BF39 -> 905.99 | BI39: 32
A40: Store 1 | B40: 110027 | C40: Outlet | D40: Burgrill | E40: 45962 | F40: RJ390568 | G40: zomato | H40: =IF(G40="POS","Direct Sale","Aggregator") -> Aggregator | I40: 7436694056 | J40: 18528960 | K40: 45962.792 | L40: =VALUE(DAY(K40)) -> 1 | M40: =TEXT(K40,"dddd") -> Saturday | N40: =TEXT(K40,"MMMM") -> November | O40: 0.79236111 | P40: =_xlfn.IFS(L40<=7,"Week 1",L40<=15, "Week 2",L40<=23,"Week 3",L40<=30,"Week 4") -> Week 1 | Q40: No | R40: 399 | S40: -75 | T40: =ABS((S40/R40)*100) -> 18.796992 | U40: 324 | V40: 32 | W40: 0 | X40: 0 | Y40: 356 | Z40: 356 | AA40: Zomato | AB40: 88.74 | AC40: 4.96 | AD40: Zomato | AE40: Burgrill | AF40: 4056 | AG40: 4056 | AO40: 32 | AP40: 0 | AX40: 356 | BD40: 356 | BE40: 324 | BG40: =BE40+BF40 -> 324 | BI40: 32
...

Sheet EDA
B2: EDA | AL2: =AJ2-AK2 -> 0
AL3: =AJ3-AK3 -> 0
A5: Objective 1 | B5: What were the Total Revenue, Total Orders, and Average Order Value (AOV) for the month?
B7: Week | C7: Revenue | D7: No. of Orders | E7: Avg Order value
B8: Week 1 | C8: 437093.54 | D8: 1198 | E8: =C8/D8 -> 364.8527
B9: Week 2 | C9: 451309.67 | D9: 1258 | E9: =C9/D9 -> 358.75172
B10: Week 3 | C10: 485338.79 | D10: 1333 | E10: =C10/D10 -> 364.09512
B11: Week 4 | C11: 404741.43 | D11: 1183 | E11: =C11/D11 -> 342.13139
B12: Total | C12: =SUM(C8:C11) -> 1778483.4 | D12: =SUM(D8:D11) -> 4972 | E12: =AVERAGE(E8:E11) -> 357.45773
B14: Note - Pivots were used to achieve the objective
A18: Objective 2 | B18: Which channel has the highest AOV?
A19: Objective 3 | B19: Which channel contributes the most to the total volume of orders?
B21: Channels | C21: Revenue | D21: No. Of Orders | E21: Avg Order value
B22: Burgrill Dine In | C22: 465524 | D22: 1366 | E22: =C22/D22 -> 340.79356
B23: magicpin | C23: 4642.92 | D23: 31 | E23: =C23/D23 -> 149.77161
B24: Swiggy | C24: 666917 | D24: 1913 | E24: =C24/D24 -> 348.62363
B25: Takeaway | C25: 102872 | D25: 251 | E25: =C25/D25 -> 409.84861
B26: TSF Dine In | C26: 1430 | D26: 7 | E26: =C26/D26 -> 204.28571
B27: Zomato | C27: 537097.51 | D27: 1404 | E27: =C27/D27 -> 382.54808
B28: Grand Total | C28: =SUM(C22:C27) -> 1778483.4 | D28: =SUM(D22:D27) -> 4972 | E28: =AVERAGE(E22:E27) -> 305.97853
B30: Note - Pivots were used to achieve the objective
A34: Objective 4 | B34: Compare the performance of Aggregators (Swiggy/Zomato) vs. Direct Channels (POS/Dine-in/Takeaway).
B37: Order Source | C37: Revenue
B38: Aggregator | C38: 1208657.4
B39: Direct Sale | C39: 569826
B41: Note - Column H introduced to classify aggregators VS Direct channels using simple IF formula
A44: Objective 5 | B44: Create a heatmap or bar chart showing transaction volume by Hour of the Day
B48: Hours | C48: Revenue
B49: 00 | C49: 171624.58
B50: 01 | C50: 141850.55
B51: 02 | C51: 102898.95
B52: 03 | C52: 85062.1
B53: 04 | C53: 74693.54
B54: 05 | C54: 7928
B55: 06 | C55: 3802
B56: 11 | C56: 12272.5
B57: 12 | C57: 18813.9
B58: 13 | C58: 33182.5
B59: 14 | C59: 52319.55
B60: 15 | C60: 64927.58
...

Sheet Conclusion
G2: Burgrill India - Rajouri garden Outlet NOV'25
D13: Analyzing the weekly sales summary by Revenue , No. of Orders and AOV | O13: Analyzing Total revenue by individual Channels of Sale
D32: Key Insights | O32: Key Insights
D33: * Week 4 attracts least customers , Additional discounts can be during week 3 | O33: * Direct channels produce only 1/3 of the Total Sales
D34: * Week 3 attracts highest footfall , so additional inventory can be introduced | O34: * TSF dine in is not producing results , some product in the segment
D35: in order to meet demand | O35: launch may change the game
D39: Analyzing No. of Orders and AOV by Individual channels | O39: Analyzing performance of Aggregators (Swiggy/Zomato) vs.
O40: Direct Channels (POS/Dine-in/Takeaway).
D59: Key Insights | O59: Key Insights
D60: * Swiggy produces highest No. of orders followed by Zomato | O60: * Direct channels produce only 1/3 of the Total Sales
D61: * Magicpin , Takeaway and TSF Dine produces lowest no. of Orders
D67: Analyzing Revenue by Hours of the day | O67: Avg % Discount given by Different channels
D89: Key Insights | O89: Key Insights
D90: * 12-1 am , 8-12 pm are the rush hours so resources can be used efficiently and accordingly | O90: * Dscount given by POS order source is very less compartively ,
D91: * From 5 am till 3 pm , engagement is less so resources can be used accordingly | O91: which can be key reason for less revenue
D98: Analyzing Top 5 customers and Revenue by them | O98: Bifurcation of repeated VS Non repeated customers by No. of Orders
D119: Key Insights | O119: Key Insights
D120: * Top customers can bring more footfall , so they should be given | O120: * Repeated customers % is very high which means the service and product quality is
D121: some extra perks/benefits for organic growth | O121: good which should be maintained going forward
D127: Revenue and No. of orders by Day of the week
D150: Key Insights
D151: * More Workforce should be provided on Weekends
D152: * Tuesday attracts least customers , so some resources can pulled away
D153: in order to manage efficiency

Sheet Notes
B2: Notes | BE2: =BC2-BD2 -> 0
B4: Note No. | C4: Column_Affected | D4: Operations exceuted | BE4: =BC4-BD4 -> 0
B5: 1 | C5: K | D5: Converted column K to custom format i.e., dd-mm-yyyy hh:mm | BE5: =BC5-BD5 -> 0
B6: 2 | C6: O | D6: Extracted hours using delimiter the text function | BE6: =BC6-BD6 -> 0
B7: 3 | C7: P | D7: Formula Used - IFS(L2<=7,"Week 1",L2<=15, "Week 2",L2<=23,"Week 3",L2<=30,"Week 4")
B8: 4 | C8: L , M ,N , O , P | D8: Columns introduced for retrieve deep insights
B9: 5 | C9: AD | D9: Cleaned the data in column Channel by using replacing magicpin-burgrill values to burgrill-magicpin also TSF- Dine In to TSF- TSF Dine In and then used delimiter to make data usable
B10: 6 | C10: H | D10: Added and additional column to distinguish direct sale vs aggregator by passing simple if formula
B11: 7 | D11: Brand - "The Sausage fest contribution is minimal in overall Revenue ,Therefore no points in segregation

Sheet Reference_sheet
A1: Invoice Number | B1: Customer Id | C1: Customer Name | D1: Paid Amount | F1: Customer Id | G1: Revenue | H1: Count Of orders | I1: Customer Repetition | K1: Customer Repetition | L1: Count | M1: Revenue
A2: RJ390531 | D2: 289 | F2: 4VS4ZNEI | G2: =SUMIF($B:$B,F2,$D:$D) -> 124 | H2: =COUNTIF($B:$B,F2) -> 2 | I2: =IF(H2>1,"Repeated customer","Non Repeated customer") -> Repeated customer | K2: Repeated customer | L2: =SUMIF($I:$I,I2,$H:$H) -> 1304 | M2: =SUMIF(I:I,K2,G:G) -> 440176.66
A3: RJ390532 | D3: 514 | F3: R7ZUEYAL | G3: =SUMIF($B:$B,F3,$D:$D) -> 167 | H3: =COUNTIF($B:$B,F3) -> 1 | I3: =IF(H3>1,"Repeated customer","Non Repeated customer") -> Non Repeated customer | K3: Non Repeated customer | L3: =SUMIF($I:$I,I3,$H:$H) -> 351 | M3: =SUMIF(I:I,K3,G:G) -> 134292.26
A4: RJ390530 | B4: 4VS4ZNEI | C4: vipin | D4: 62 | F4: RJFXN3YM | G4: =SUMIF($B:$B,F4,$D:$D) -> 307529 | H4: =COUNTIF($B:$B,F4) -> 927 | I4: =IF(H4>1,"Repeated customer","Non Repeated customer") -> Repeated customer
A5: RJ390529 | B5: R7ZUEYAL | C5: naman | D5: 167 | F5: BCTCUL8A | G5: =SUMIF($B:$B,F5,$D:$D) -> 374 | H5: =COUNTIF($B:$B,F5) -> 1 | I5: =IF(H5>1,"Repeated customer","Non Repeated customer") -> Non Repeated customer
A6: RJ390533 | D6: 375 | F6: E9WZ2UG5 | G6: =SUMIF($B:$B,F6,$D:$D) -> 167 | H6: =COUNTIF($B:$B,F6) -> 1 | I6: =IF(H6>1,"Repeated customer","Non Repeated customer") -> Non Repeated customer
A7: RJ390537 | D7: 316 | F7: GIDIRMS3 | G7: =SUMIF($B:$B,F7,$D:$D) -> 387 | H7: =COUNTIF($B:$B,F7) -> 1 | I7: =IF(H7>1,"Repeated customer","Non Repeated customer") -> Non Repeated customer
A8: RJ390538 | D8: 340 | F8: I8Y3EPU8 | G8: =SUMIF($B:$B,F8,$D:$D) -> 463 | H8: =COUNTIF($B:$B,F8) -> 2 | I8: =IF(H8>1,"Repeated customer","Non Repeated customer") -> Repeated customer
A9: RJ390539 | D9: 240 | F9: MJHTLH2P | G9: =SUMIF($B:$B,F9,$D:$D) -> 627 | H9: =COUNTIF($B:$B,F9) -> 1 | I9: =IF(H9>1,"Repeated customer","Non Repeated customer") -> Non Repeated customer
A10: RJ390540 | D10: 446 | F10: ZQVQWXQQ | G10: =SUMIF($B:$B,F10,$D:$D) -> 387 | H10: =COUNTIF($B:$B,F10) -> 1 | I10: =IF(H10>1,"Repeated customer","Non Repeated customer") -> Non Repeated customer
A11: RJ390541 | D11: 332 | F11: D8MDIGHA | G11: =SUMIF($B:$B,F11,$D:$D) -> 147 | H11: =COUNTIF($B:$B,F11) -> 1 | I11: =IF(H11>1,"Repeated customer","Non Repeated customer") -> Non Repeated customer
A12: RJ390542 | D12: 206 | F12: CSNWY5P7 | G12: =SUMIF($B:$B,F12,$D:$D) -> 356 | H12: =COUNTIF($B:$B,F12) -> 1 | I12: =IF(H12>1,"Repeated customer","Non Repeated customer") -> Non Repeated customer
A13: RJ390543 | D13: 381 | F13: GFCWJ7BX | G13: =SUMIF($B:$B,F13,$D:$D) -> 1108 | H13: =COUNTIF($B:$B,F13) -> 1 | I13: =IF(H13>1,"Repeated customer","Non Repeated customer") -> Non Repeated customer
A14: RJ390544 | D14: 407.16 | F14: Z3PZWUEE | G14: =SUMIF($B:$B,F14,$D:$D) -> 206 | H14: =COUNTIF($B:$B,F14) -> 1 | I14: =IF(H14>1,"Repeated customer","Non Repeated customer") -> Non Repeated customer
A15: RJ390545 | D15: 196 | F15: 7111VIGN | G15: =SUMIF($B:$B,F15,$D:$D) -> 542 | H15: =COUNTIF($B:$B,F15) -> 2 | I15: =IF(H15>1,"Repeated customer","Non Repeated customer") -> Repeated customer
A16: RJ390534 | B16: RJFXN3YM | C16: Burgrill | D16: 302 | F16: RZF7ACWG | G16: =SUMIF($B:$B,F16,$D:$D) -> 398 | H16: =COUNTIF($B:$B,F16) -> 1 | I16: =IF(H16>1,"Repeated customer","Non Repeated customer") -> Non Repeated customer
A17: RJ390535 | B17: BCTCUL8A | C17: ms | D17: 374 | F17: CSJG3RLQ | G17: =SUMIF($B:$B,F17,$D:$D) -> 5457 | H17: =COUNTIF($B:$B,F17) -> 8 | I17: =IF(H17>1,"Repeated customer","Non Repeated customer") -> Repeated customer
A18: RJ390536 | B18: RJFXN3YM | C18: Burgrill | D18: 70 | F18: KDH32EH3 | G18: =SUMIF($B:$B,F18,$D:$D) -> 187 | H18: =COUNTIF($B:$B,F18) -> 1 | I18: =IF(H18>1,"Repeated customer","Non Repeated customer") -> Non Repeated customer
A19: RJ390546 | D19: 447 | F19: TTRZHK6Y | G19: =SUMIF($B:$B,F19,$D:$D) -> 104 | H19: =COUNTIF($B:$B,F19) -> 1 | I19: =IF(H19>1,"Repeated customer","Non Repeated customer") -> Non Repeated customer
A20: RJ390547 | D20: 352 | F20: GPFKCY88 | G20: =SUMIF($B:$B,F20,$D:$D) -> 722 | H20: =COUNTIF($B:$B,F20) -> 3 | I20: =IF(H20>1,"Repeated customer","Non Repeated customer") -> Repeated customer
A21: RJ390549 | B21: E9WZ2UG5 | C21: sidhi | D21: 167 | F21: N3M6HDPP | G21: =SUMIF($B:$B,F21,$D:$D) -> 104 | H21: =COUNTIF($B:$B,F21) -> 1 | I21: =IF(H21>1,"Repeated customer","Non Repeated customer") -> Non Repeated customer
A22: RJ390550 | D22: 584 | F22: 1WSEBUNY | G22: =SUMIF($B:$B,F22,$D:$D) -> 57 | H22: =COUNTIF($B:$B,F22) -> 1 | I22: =IF(H22>1,"Repeated customer","Non Repeated customer") -> Non Repeated customer
